Workbook

Sheet All
D1: =F1+P1 -> 18.23 | F1: =SUM(F2:N2) -> 16.84 | P1: =SUM(P2:Q2) -> 1.39
D2: 18.23 | E2: 16.84 | F2: 4.14 | G2: 5.1 | H2: 0.43 | I2: 1.83 | J2: 0.82 | K2: 0.62 | L2: 1.74 | M2: 0.92 | N2: 1.24 | O2: 1.39 | P2: 0.39 | Q2: 1 | R2: 4.64 | S2: 3.51 | T2: 0.77 | U2: 0.47 | V2: 1.77 | W2: 1.13 | X2: 3.9 | Y2: 2.85 | Z2: 1.05 | AA2: 24.1 | AB2: 4.37 | AC2: 11.16 | AD2: 0.64 | AE2: 3.83 | AF2: 4.1 | AG2: 3.33 | AH2: 0.53 | AI2: 0.38 | AJ2: 1.83 | AK2: 0.59 | AL2: 1.78 | AM2: 0.9 | AN2: 0.88 | AO2: 13.89 | AP2: 5.61 | AQ2: 5.28 | AR2: 3.89 | AS2: =AQ2-AR2 -> 1.39 | AT2: 2.91 | AU2: 0.09 | AV2: 5.47 | AW2: 0.94 | AX2: 4.53 | AY2: 2.94 | AZ2: 0.78 | BA2: 1.85 | BB2: 0.25 | BC2: 0.06 | BD2: 2.41 | BE2: 1.41 | BF2: 1 | BG2: 6.12 | BH2: 4.75 | BI2: 1.37 | BJ2: 2.78 | BK2: 1.01 | BL2: =BJ2-BK2 -> 1.77 | BM2: 10.41 | BN2: 8.41 | BO2: 2
A3: month | B3: Headline CPI | C3: Core CPI | D3: Food and non-alcoholic beverages (NAB) | E3: Food | F3: Cereal products | G3: Meat | H3: Fish and other seafood | I3: Milk, other dairy products and eggs | J3: Oils and fats | K3: Fruit and nuts | L3: Vegetables | M3: Sugar, confectionary and desserts | N3: Other food | O3: Non-alcoholic beverages | P3: Hot beverages | Q3: Cold beverages | R3: Alcoholic beverages and tobacco | S3: Alcoholic beverages | T3: Spirits | U3: Wine | V3: Beer | W3: Tobacco | X3: Clothing and footwear | Y3: Clothing | Z3: Footwear | AA3: Housing and utilities | AB3: Actual rentals for housing | AC3: Owners' equivalent rent | AD3: Maintenance and repairs | AE3: Water supply and miscellaneous services | AF3: Electricity and other fuels | AG3: Furnishings, household equipment and routine maintenance | AH3: Furniture, furnishings and carpets | AI3: Appliances, tableware and equipment | AJ3: Goods and services for routine household maintenance | AK3: Supplies and services - Domestic services | AL3: Health | AM3: Medicines and health products | AN3: Health services | AO3: Transport | AP3: Purchase of vehicles | AQ3: Operation of personal transport equipment | AR3: Fuel | AS3: Other services | AT3: Passenger transport services | AU3: Transport services of goods | AV3: Information and communication | AW3: Information and communication equipment | AX3: Information and communication services | AY3: Recreation, sport and culture | AZ3: Recreational goods | BA3: Recreational and cultural services | BB3: Newspapers, books and stationery | BC3: Package holidays | BD3: Education | BE3: Primary and secondary education | BF3: Tertiary education | BG3: Restaurants and accommodation services | BH3: Restaurants | BI3: Accommodation services | BJ3: Personal care and miscellaneous services | BK3: Personal care | BL3: Other services | BM3: Insurance and financial services | BN3: Insurance | BO3: Financial services
A4: 39844 | B4: 8.1145585 | C4: 7.1274298 | D4: 15.74344 | E4: 16.326531 | F4: 27.777778 | G4: 7.8740157 | H4: 19.207317 | I4: 14.825581 | J4: 30.81571 | K4: 6.4516129 | L4: 19.005848 | M4: 13.00813 | N4: 18.209877 | O4: 12.5 | P4: 23.371648 | Q4: 8.9974293 | R4: 10.1983 | S4: 8.4033613 | T4: 12.790698 | U4: 6.9892473 | V4: 6.8870523 | W4: 12.849162 | X4: 3.902439 | Y4: 4.1946309 | Z4: 3.1626506 | AA4: 8.9552239 | AB4: 7.8 | AC4: 6.9811321 | AD4: 16.28866 | AE4: 4.9295775 | AF4: 30.985915 | AG4: 6.0064935 | AH4: 0.31397174 | AI4: 10.773481 | AJ4: 8.2568807 | AK4: 6.6059226 | AL4: 7.7319588 | AM4: 7.5862069 | AN4: 7.5418994 | AO4: 0 | AP4: 1.0909091 | AQ4: -13.314448 | AR4: -20.639535 | AS4: 12.686567 | AT4: 17.032967 | AU4: #N/A | AV4: 0.65666041 | AW4: -5.0985859 | AX4: 1.4084507 | AY4: 8.490566 | AZ4: 10.176991 | BA4: 5.1282051 | BB4: 9.0909091 | BC4: #N/A | BD4: 6.8852459 | BE4: 7.3943662 | BF4: 6.8047337 | BG4: 13.212435 | BH4: 12.99435 | BI4: 13.948498 | BJ4: 10.826211 | BK4: 12.068966 | BL4: 19.467213 | BM4: #N/A | BN4: 6.3694268 | BO4: 17.142857
A5: 39872 | B5: 8.2938389 | C5: 7.9569892 | D5: 15.74344 | E5: 16.034985 | F5: 23.952096 | G5: 9.8143236 | H5: 19.877676 | I5: 13.832853 | J5: 25.443787 | K5: 8.8495575 | L5: 18.823529 | M5: 13.414634 | N5: 18.82716 | O5: 15.362319 | P5: 23.371648 | Q5: 13.589744 | R5: 10.084034 | S5: 7.7134986 | T5: 11.111111 | U5: 6.9518717 | V5: 5.9139785 | W5: 14.24581 | X5: 4.7077922 | Y5: 5.0251256 | Z5: 3.6144578 | AA5: 8.9552239 | AB5: 7.8 | AC5: 6.9811321 | AD5: 16.632444 | AE5: 4.9295775 | AF5: 30.28169 | AG5: 6.8292683 | AH5: 1.2628256 | AI5: 14.623955 | AJ5: 8.9449541 | AK5: 6.6059226 | AL5: 9.0909091 | AM5: 7.816092 | AN5: 10.12987 | AO5: 1.5250545 | AP5: 2.003643 | AQ5: -8.3333333 | AR5: -13.920455 | AS5: 14.179104 | AT5: 15.531335 | AU5: #N/A | AV5: 0.657277 | AW5: -5.6605671 | AX5: 1.4084507 | AY5: 9.7484277 | AZ5: 10.706402 | BA5: 6.5934066 | BB5: 11.620795 | BC5: #N/A | BD5: 6.8852459 | BE5: 7.3943662 | BF5: 6.8047337 | BG5: 13.367609 | BH5: 13.202247 | BI5: 13.742072 | BJ5: 11.634349 | BK5: 13.333333 | BL5: 19.467213 | BM5: #N/A | BN5: 7.9027356 | BO5: 17.142857
A6: 39903 | B6: 8.411215 | C6: 8.0679406 | D6: 14.655172 | E6: 15.273775 | F6: 20.05814 | G6: 10.904255 | H6: 20.743034 | I6: 12.290503 | J6: 11.924119 | K6: 12.975391 | L6: 18.452381 | M6: 15.447154 | N6: 16.86747 | O6: 13.202247 | P6: 26.61597 | Q6: 9.6296296 | R6: 10.455764 | S6: 9.0425532 | T6: 10.242588 | U6: 8.616188 | V6: 8.0939948 | W6: 13.56383 | X6: 4.8543689 | Y6: 5.1752922 | Z6: 3.7593985 | AA6: 8.0882353 | AB6: 6.640625 | AC6: 5.5350554 | AD6: 17.525773 | AE6: 4.9295775 | AF6: 30.28169 | AG6: 7.2815534 | AH6: 1.8297534 | AI6: 14.876033 | AJ6: 9.0293454 | AK6: 6.0810811 | AL6: 11.547912 | AM6: 13.47032 | AN6: 10.12987 | AO6: 0.64102564 | AP6: 2.1857923 | AQ6: -8.8541667 | AR6: -14.736842 | AS6: 14.59854 | AT6: 13.821138 | AU6: #N/A | AV6: 0.65789474 | AW6: -5.1412315 | AX6: 1.4084507 | AY6: 14.779874 | AZ6: 12.513843 | BA6: 19.926874 | BB6: 12.765957 | BC6: #N/A | BD6: 10.429448 | BE6: 11.803279 | BF6: 8.5872576 | BG6: 13.636364 | BH6: 12.777778 | BI6: 14.579055 | BJ6: 11.84573 | BK6: 15.498938 | BL6: 19.467213 | BM6: #N/A | BN6: 7.2507553 | BO6: 19.480519
A7: 39933 | B7: 8.372093 | C7: 8.2627119 | D7: 13.597734 | E7: 13.597734 | F7: 17.714286 | G7: 10.61008 | H7: 16.071429 | I7: 12.672176 | J7: 1.2626263 | K7: 12.337662 | L7: 17.888563 | M7: 16.465863 | N7: 17.313433 | O7: 14.24581 | P7: 31.320755 | Q7: 9.3137255 | R7: 10.933333 | S7: 9.2592593 | T7: 10.106383 | U7: 9.0673575 | V7: 8.3550914 | W7: 13.492063 | X7: 5.3398058 | Y7: 5.6761269 | Z7: 4.0540541 | AA7: 8.0684597 | AB7: 6.640625 | AC7: 5.5350554 | AD7: 16.938776 | AE7: 4.9295775 | AF7: 29.370629 | AG7: 6.7524116 | AH7: 0.078369906 | AI7: 16.968011 | AJ7: 8.5201794 | AK7: 6.0810811 | AL7: 12.285012 | AM7: 15.525114 | AN7: 10.12987 | AO7: 1.0548523 | AP7: 2.919708 | AQ7: -11.650485 | AR7: -17.274939 | AS7: 14.319809 | AT7: 15.068493 | AU7: #N/A | AV7: 0.94339623 | AW7: -6.395112 | AX7: 1.9586507 | AY7: 15.264798 | AZ7: 12.074643 | BA7: 21.195652 | BB7: 12.5 | BC7: #N/A | BD7: 10.429448 | BE7: 11.803279 | BF7: 8.5872576 | BG7: 13.283208 | BH7: 13.498623 | BI7: 13.963039 | BJ7: 11.506849 | BK7: 15.611814 | BL7: 17.303823 | BM7: #N/A | BN7: 7.2507553 | BO7: 19.480519
A8: 39964 | B8: 8.0831409 | C8: 8.4566596 | D8: 12.256267 | E8: 12.534819 | F8: 10.483871 | G8: 10.23622 | H8: 13.953488 | I8: 12.84153 | J8: -3.4398034 | K8: 15.124153 | L8: 17.44186 | M8: 16.205534 | N8: 17.595308 | O8: 15.041783 | P8: 33.082707 | Q8: 9.7799511 | R8: 10.638298 | S8: 8.9473684 | T8: 10.344828 | U8: 9.0439276 | V8: 8.0729167 | W8: 13.456464 | X8: 5 | Y8: 5.4908486 | Z8: 3.742515 | AA8: 8.0684597 | AB8: 6.640625 | AC8: 5.5350554 | AD8: 15 | AE8: 4.9295775 | AF8: 30.28169 | AG8: 7.0626003 | AH8: 0.94711918 | AI8: 16 | AJ8: 8.7053571 | AK8: 6.0810811 | AL8: 11.435523 | AM8: 13.963964 | AN8: 10.649351 | AO8: 0.6263048 | AP8: 4.9541284 | AQ8: -16.589862 | AR8: -22.425629 | AS8: 13.711584 | AT8: 14.402174 | AU8: #N/A | AV8: 0.84825636 | AW8: -7.6720648 | AX8: 1.9586507 | AY8: 13.957055 | AZ8: 11.555076 | BA8: 20.976492 | BB8: 8.0229226 | BC8: #N/A | BD8: 10.429448 | BE8: 11.803279 | BF8: 8.5872576 | BG8: 12.903226 | BH8: 12.5 | BI8: 13.496933 | BJ8: 11.780822 | BK8: 15.932914 | BL8: 17.303823 | BM8: #N/A | BN8: 7.2507553 | BO8: 19.480519
A9: 39994 | B9: 7.0615034 | C9: 7.7405858 | D9: 10.136986 | E9: 9.8360656 | F9: 5.9278351 | G9: 8.5492228 | H9: 11.396011 | I9: 13.079019 | J9: -7.1599045 | K9: 10.185185 | L9: 17.251462 | M9: 14.84375 | N9: 15.229885 | O9: 14.088398 | P9: 27.797834 | Q9: 9.5354523 | R9: 10.638298 | S9: 8.6614173 | T9: 10.31746 | U9: 8.2051282 | V9: 8.0729167 | W9: 13.157895 | X9: 4.8154093 | Y9: 5.1239669 | Z9: 4.0419162 | AA9: 7.2115385 | AB9: 5.7034221 | AC9: 4.6931408 | AD9: 13.333333 | AE9: 4.9295775 | AF9: 28.472222 | AG9: 6.9952305 | AH9: 0.23622047 | AI9: 15.934066 | AJ9: 8.7527352 | AK9: 6.3596491 | AL9: 11.165049 | AM9: 13.199105 | AN9: 10.649351 | AO9: -2.2222222 | AP9: 4 | AQ9: -18.543046 | AR9: -24.94577 | AS9: 13.14554 | AT9: 4.4226044 | AU9: #N/A | AV9: 0.56550424 | AW9: -10.365361 | AX9: 1.9586507 | AY9: 13.496933 | AZ9: 11.410118 | BA9: 20.540541 | BB9: 7.0175439 | BC9: #N/A | BD9: 10.429448 | BE9: 11.803279 | BF9: 8.5872576 | BG9: 12.285012 | BH9: 11.2 | BI9: 13.877551 | BJ9: 11.780822 | BK9: 15.448852 | BL9: 17.303823 | BM9: #N/A | BN9: 7.5528701 | BO9: 20
A10: 40025 | B10: 6.741573 | C10: 7.9002079 | D10: 8.3783784 | E10: 7.8167116 | F10: 3.8071066 | G10: 6.4267352 | H10: 11.267606 | I10: 11.229947 | J10: -8.9622642 | K10: 9.9307159 | L10: 14.534884 | M10: 12.21374 | N10: 13.202247 | O10: 14.754098 | P10: 26.33452 | Q10: 11.407767 | R10: 11.671088 | S10: 8.0939948 | T10: 9.7368421 | U10: 7.9081633 | V10: 7.7922078 | W10: 15.789474 | X10: 5.2884615 | Y10: 5.4455446 | Z10: 4.6407186 | AA10: 8.2159624 | AB10: 5.7034221 | AC10: 4.6931408 | AD10: 13.009709 | AE10: 9.0909091 | AF10: 27.272727 | AG10: 6.5079365 | AH10: 0.31695721 | AI10: 13.414634 | AJ10: 8.9519651 | AK10: 6.3596491 | AL10: 10.895884 | AM10: 11.699779 | AN10: 10.649351 | AO10: -3.3663366 | AP10: 2.8933092 | AQ10: -20 | AR10: -26.166329 | AS10: 12.009238 | AT10: 3.1553398 | AU10: #N/A | AV10: 0.56603774 | AW10: -10.53869 | AX10: 1.9586507 | AY10: 13.914373 | AZ10: 11.948332 | BA10: 20.323741 | BB10: 7.2254335 | BC10: #N/A | BD10: 10.429448 | BE10: 11.803279 | BF10: 8.5872576 | BG10: 10.361446 | BH10: 10.875332 | BI10: 9.4674556 | BJ10: 13.043478 | BK10: 15.416667 | BL10: 14.990138 | BM10: #N/A | BN10: 10.542169 | BO10: 17.884131
A11: 40056 | B11: 6.0267857 | C11: 7.6446281 | D11: 6.9333333 | E11: 6.3829787 | F11: 0.24630542 | G11: 5.3846154 | H11: 10.335196 | I11: 9.9737533 | J11: -11.36891 | K11: 11.08545 | L11: 13.276836 | M11: 10.074627 | N11: 13.687151 | O11: 13.709677 | P11: 20.608108 | Q11: 11.594203 | R11: 12.532637 | S11: 8.0939948 | T11: 9.9737533 | U11: 7.3417722 | V11: 8.0729167 | W11: 18.575064 | X11: 5.0955414 | Y11: 5.0819672 | Z11: 4.3090639 | AA11: 7.9254079 | AB11: 5.7034221 | AC11: 4.6931408 | AD11: 8.3179298 | AE11: 9.3959732 | AF11: 25.68306 | AG11: 5.9936909 | AH11: 0.078926598 | AI11: 11.27321 | AJ11: 8.9324619 | AK11: 6.3596491 | AL11: 11.111111 | AM11: 12.114537 | AN11: 10.649351 | AO11: -2.6 | AP11: 3.8112523 | AQ11: -19.787234 | AR11: -26.458333 | AS11: 12.240185 | AT11: 4.1769042 | AU11: #N/A | AV11: 1.304753 | AW11: -11.603705 | AX11: 2.5668449 | AY11: 11.844078 | AZ11: 8.2291667 | BA11: 21.582734 | BB11: 5.3977273 | BC11: #N/A | BD11: 10.429448 | BE11: 11.803279 | BF11: 8.5872576 | BG11: 9.8321343 | BH11: 10.55409 | BI11: 7.3643411 | BJ11: 12.432432 | BK11: 13.90593 | BL11: 14.990138 | BM11: #N/A | BN11: 10.542169 | BO11: 16.129032
A12: 40086 | B12: 6.4444444 | C12: 6.9672131 | D12: 5.2493438 | E12: 4.9868766 | F12: -1.9323671 | G12: 4.0712468 | H12: 7.3569482 | I12: 7.1611253 | J12: -12.814645 | K12: 12.790698 | L12: 15.625 | M12: 10 | N12: 11.382114 | O12: 11.609499 | P12: 16.721311 | Q12: 10.26253 | R12: 11.886305 | S12: 8.0519481 | T12: 9.6605744 | U12: 7.0175439 | V12: 6.9587629 | W12: 17.293233 | X12: 4.7619048 | Y12: 5.0653595 | Z12: 4.4510386 | AA12: 7.6212471 | AB12: 5.2631579 | AC12: 4.8300537 | AD12: 7.3126143 | AE12: 9.3959732 | AF12: 25 | AG12: 5.3208138 | AH12: -0.94488189 | AI12: 9.5800525 | AJ12: 8.3870968 | AK12: 6.2770563 | AL12: 11.111111 | AM12: 12.77533 | AN12: 10.649351 | AO12: -1.4084507 | AP12: 2.7027027 | AQ12: -11.738149 | AR12: -17.225951 | AS12: 11.954023 | AT12: 1.4319809 | AU12: #N/A | AV12: 0.93370682 | AW12: -11.657033 | AX12: 2.1390374 | AY12: 11.360239 | AZ12: 6.5488565 | BA12: 19.929453 | BB12: 10.724638 | BC12: #N/A | BD12: 10.429448 | BE12: 11.803279 | BF12: 8.5872576 | BG12: 9.7852029 | BH12: 11.081794 | BI12: 7.7071291 | BJ12: 11.764706 | BK12: 13.104839 | BL12: 14.09002 | BM12: #N/A | BN12: 11.111111 | BO12: 7.8341014
A13: 40117 | B13: 6.4444444 | C13: 6.5306122 | D13: 5.4830287 | E13: 5.2083333 | F13: -2.173913 | G13: 4.0712468 | H13: 7.712766 | I13: 7.6923077 | J13: -13.926941 | K13: 13.519814 | L13: 16.576087 | M13: 8 | N13: 9.3085106 | O13: 12.137203 | P13: 14.469453 | Q13: 11.217184 | R13: 11.597938 | S13: 8.0519481 | T13: 9.6605744 | U13: 7.2864322 | V13: 6.9587629 | W13: 16.41791 | X13: 4.9206349 | Y13: 5.2202284 | Z13: 4.4444444 | AA13: 7.3732719 | AB13: 5.2631579 | AC13: 4.8300537 | AD13: 6.3176895 | AE13: 9.3959732 | AF13: 23.783784 | AG13: 4.6801872 | AH13: -0.94488189 | AI13: 8.5078534 | AJ13: 7.7087794 | AK13: 6.2770563 | AL13: 11.111111 | AM13: 12.77533 | AN13: 10.649351 | AO13: -2.020202 | AP13: 2.7027027 | AQ13: -13.59447 | AR13: -18.894009 | AS13: 11.187215 | AT13: 1.4285714 | AU13: #N/A | AV13: 0.46685341 | AW13: -15.456975 | AX13: 2.1390374 | AY13: 10.698366 | AZ13: 4.6248715 | BA13: 19.929453 | BB13: 11.594203 | BC13: #N/A | BD13: 10.429448 | BE13: 11.803279 | BF13: 8.5872576 | BG13: 7.9254079 | BH13: 7.6335878 | BI13: 8.3333333 | BJ13: 10.582011 | BK13: 11.84739 | BL13: 8.6556169 | BM13: #N/A | BN13: 12.121212 | BO13: 7.8341014
A14: 40147 | B14: 6.2084257 | C14: 6.3136456 | D14: 4.6632124 | E14: 4.1343669 | F14: -2.8846154 | G14: 3.5264484 | H14: 5.974026 | I14: 9.0206186 | J14: -13.657407 | K14: 13.716814 | L14: 12.432432 | M14: 7.9710145 | N14: 8.7301587 | O14: 10.909091 | P14: 13.291139 | Q14: 10.638298 | R14: 11.311054 | S14: 8.0519481 | T14: 9.6605744 | U14: 7.5376884 | V14: 6.9587629 | W14: 16.666667 | X14: 5.2380952 | Y14: 5.2202284 | Z14: 4.5925926 | AA14: 7.3732719 | AB14: 5.2631579 | AC14: 4.8300537 | AD14: 6.2836625 | AE14: 9.3959732 | AF14: 24.324324 | AG14: 4.2056075 | AH14: -1.6483516 | AI14: 6.9100391 | AJ14: 7.7087794 | AK14: 6.2770563 | AL14: 10.047847 | AM14: 10.537634 | AN14: 10.649351 | AO14: -0.81799591 | AP14: 2.7075812 | AQ14: -10.071942 | AR14: -14.769976 | AS14: 10.909091 | AT14: 1.9047619 | AU14: #N/A | AV14: 0.37383178 | AW14: -17.117603 | AX14: 2.1390374 | AY14: 7.9710145 | AZ14: 2.2132797 | BA14: 19.929453 | BB14: 6.5217391 | BC14: #N/A | BD14: 10.429448 | BE14: 11.803279 | BF14: 8.5872576 | BG14: 7.6566125 | BH14: 7.5949367 | BI14: 7.7071291 | BJ14: 10.582011 | BK14: 10.27668 | BL14: 8.6556169 | BM14: #N/A | BN14: 12.121212 | BO14: 7.8341014
A15: 40178 | B15: 6.4444444 | C15: 6.2880325 | D15: 3.5989717 | E15: 2.8132992 | F15: -3.125 | G15: 2.2277228 | H15: 4.6511628 | I15: 8.7403599 | J15: -13.657407 | K15: 10.315789 | L15: 6.2992126 | M15: 8.7912088 | N15: 7.6719577 | O15: 10.649351 | P15: 12.539185 | Q15: 10.165485 | R15: 11.311054 | S15: 7.7922078 | T15: 8.8311688 | U15: 7.5566751 | V15: 6.9587629 | W15: 16.62531 | X15: 4.8973144 | Y15: 4.8701299 | Z15: 4.4313146 | AA15: 7.3226545 | AB15: 5.0092764 | AC15: 4.0564374 | AD15: 5.8928571 | AE15: 9.3959732 | AF15: 23.655914 | AG15: 3.7209302 | AH15: -1.9685039 | AI15: 6.3802083 | AJ15: 7.4152542 | AK15: 5.7692308 | AL15: 10.047847 | AM15: 10.775862 | AN15: 10.649351 | AO15: 3.6016949 | AP15: 2.3423423 | AQ15: 8.7323944 | AR15: 7.6696165 | AS15: 10.11236 | AT15: 0.46728972 | AU15: #N/A | AV15: 0.18674136 | AW15: -19.52776 | AX15: 2.1390374 | AY15: 9.2240117 | AZ15: 3.058104 | BA15: 19.507909 | BB15: 11.142061 | BC15: #N/A | BD15: 10.429448 | BE15: 11.803279 | BF15: 8.5872576 | BG15: 7.816092 | BH15: 8.5642317 | BI15: 6.4272212 | BJ15: 10.582011 | BK15: 9.6078431 | BL15: 8.6556169 | BM15: #N/A | BN15: 12.121212 | BO15: 7.8341014
... A62: 41608 | B62: 5.4054054 | C62: 5.2721088 | D62: 3.7037037 | E62: 3.7037037 | F62: 4.3298969 | G62: 0.19305019 | H62: 5.1282051 | I62: 7.9399142 | J62: 3.877551 | K62: 1.5280136 | L62: 4.8979592 | M62: 6.3492063 | N62: 5.4878049 | O62: 5.0916497 | P62: 7.4441687 | Q62: 4.4362292 | R62: 6.8181818 | S62: 7.3929961 | T62: 6.3872255 | U62: 3.4 | V62: 8.9385475 | W62: 5.3475936 | X62: 3.2122905 | Y62: 3.4139403 | Z62: 2.9569892 | AA62: 5.3571429 | AB62: 4.7765794 | AC62: 4.5385779 | AD62: 4.3090639 | AE62: 8.0188679 | AF62: 7.3863636 | AG62: 3.6879433 | AH62: -0.17256255 | AI62: 2.6666667 | AJ62: 5.7921635 | AK62: 5.8519793 | AL62: 4.5537341 | AM62: 3.2590051 | AN62: 6.3339731 | AO62: 5.7245081 | AP62: 4.0925267 | AQ62: 6.9767442 | AR62: 7.7060932 | AS62: 4.4982699 | AT62: 5.6057866 | AU62: #N/A | AV62: 1.0669253 | AW62: -12.286515 | AX62: 1.8867925 | AY62: 2.6666667 | AZ62: 0.78651685 | BA62: 2.8833552 | BB62: 3.930131 | BC62: #N/A | BD62: 9.0128755 | BE62: 9.0497738 | BF62: 8.9463221 | BG62: 7.2202166 | BH62: 6.4579256 | BI62: 8.801214 | BJ62: 7.2164948 | BK62: 5.7823129 | BL62: 2.8400598 | BM62: #N/A | BN62: 8.5972851 | BO62: 5.5147059
A63: 41639 | B63: 5.3956835 | C63: 5.2631579 | D63: 3.4979424 | E63: 3.4979424 | F63: 4.3209877 | G63: 0 | H63: 5.1612903 | I63: 7.2340426 | J63: 3.0425963 | K63: 0.48701299 | L63: 5.4393305 | M63: 5.8355438 | N63: 5.4989817 | O63: 4.040404 | P63: 6.6502463 | Q63: 3.3027523 | R63: 7.0208729 | S63: 7.6023392 | T63: 5.4 | U63: 4.8582996 | V63: 9.310987 | W63: 5.8823529 | X63: 3.4867503 | Y63: 3.6931818 | Z63: 2.8187919 | AA63: 5.5062167 | AB63: 5.0458716 | AC63: 4.6546547 | AD63: 3.2448378 | AE63: 8.0188679 | AF63: 7.082153 | AG63: 3.3898305 | AH63: -1.2068966 | AI63: 2.4360536 | AJ63: 5.4054054 | AK63: 5.6313993 | AL63: 4.5537341 | AM63: 2.5641026 | AN63: 6.3339731 | AO63: 6.25 | AP63: 4.0925267 | AQ63: 8.8129496 | AR63: 9.9457505 | AS63: 4.5060659 | AT63: 4.5855379 | AU63: #N/A | AV63: 1.0679612 | AW63: -13.285273 | AX63: 1.8867925 | AY63: 2.9451138 | AZ63: 0.22446689 | BA63: 2.8833552 | BB63: 5.7522124 | BC63: 13.317191 | BD63: 9.0128755 | BE63: 9.0497738 | BF63: 8.9463221 | BG63: 7.1684588 | BH63: 6.7961165 | BI63: 8.4592145 | BJ63: 6.9958848 | BK63: 5.4145516 | BL63: 2.8400598 | BM63: #N/A | BN63: 8.1081081 | BO63: 5.5147059
A64: 41670 | B64: 5.9245961 | C64: 5.2453469 | D64: 4.2857143 | E64: 4.0733198 | F64: 4.4989775 | G64: 1.7241379 | H64: 6.1571125 | I64: 6.7368421 | J64: 2.4242424 | K64: 2.4590164 | L64: 6.2880325 | M64: 5.7742782 | N64: 6.8548387 | O64: 4.5908184 | P64: 5.5690073 | Q64: 4.1666667 | R64: 6.9811321 | S64: 7.7369439 | T64: 6.1386139 | U64: 4.1749503 | V64: 9.4619666 | W64: 5.1601423 | X64: 3.7604457 | Y64: 3.8243626 | Z64: 3.2128514 | AA64: 5.3191489 | AB64: 5.0458716 | AC64: 4.6546547 | AD64: 3.0612245 | AE64: 8.0188679 | AF64: 7.082153 | AG64: 3.2440056 | AH64: -1.7226529 | AI64: 1.9300362 | AJ64: 5.5743243 | AK64: 5.6313993 | AL64: 4.5537341 | AM64: 2.9059829 | AN64: 6.3339731 | AO64: 7.8711986 | AP64: 4.0707965 | AQ64: 12.545455 | AR64: 14.625229 | AS64: 5.3633218 | AT64: 4.5855379 | AU64: #N/A | AV64: 1.0679612 | AW64: -13.335066 | AX64: 1.8867925 | AY64: 3.4666667 | AZ64: 0.22396417 | BA64: 2.7486911 | BB64: 12.612613 | BC64: 8.0681818 | BD64: 9.0128755 | BE64: 9.0497738 | BF64: 8.9463221 | BG64: 7.2695035 | BH64: 6.7567568 | BI64: 9.2920354 | BJ64: 6.9672131 | BK64: 5.0505051 | BL64: 4.2836041 | BM64: #N/A | BN64: 8.1081081 | BO64: 3.3391916
A65: 41698 | B65: 5.8614565 | C65: 5.3511706 | D65: 5.3278689 | E65: 5.5441478 | F65: 7.4226804 | G65: 3.1128405 | H65: 7.4152542 | I65: 6.2370062 | J65: 2.6 | K65: 3.6789298 | L65: 7.1868583 | M65: 4.6632124 | N65: 6.2626263 | O65: 3.777336 | P65: 5.2884615 | Q65: 3.4358047 | R65: 6.741573 | S65: 6.6921606 | T65: 6.7729084 | U65: 4.8096192 | V65: 7.6225045 | W65: 5.3380783 | X65: 4.3115438 | Y65: 4.3785311 | Z65: 4.0160643 | AA65: 5.4964539 | AB65: 5.0458716 | AC65: 4.6546547 | AD65: 4.0816327 | AE65: 8.0188679 | AF65: 7.082153 | AG65: 3.8135593 | AH65: 0 | AI65: 2.5362319 | AJ65: 5.5743243 | AK65: 5.6313993 | AL65: 5.1327434 | AM65: 3.4129693 | AN65: 6.1482821 | AO65: 8.1272085 | AP65: 4.7787611 | AQ65: 12.367491 | AR65: 13.932981 | AS65: 6.0344828 | AT65: 4.3936731 | AU65: #N/A | AV65: 1.1661808 | AW65: -11.682119 | AX65: 1.8867925 | AY65: 2.5099075 | AZ65: 0.11185682 | BA65: 1.1597938 | BB65: 9.8901099 | BC65: 8.8505747 | BD65: 9.0128755 | BE65: 9.0497738 | BF65: 8.9463221 | BG65: 7.6106195 | BH65: 6.7567568 | BI65: 10.882353 | BJ65: 6.4202335 | BK65: 5.0505051 | BL65: 4.2836041 | BM65: #N/A | BN65: 7.0981211 | BO65: 3.3391916
A66: 41729 | B66: 6.1403509 | C66: 5.6291391 | D66: 6.9815195 | E66: 7.4074074 | F66: 9.3167702 | G66: 4.0856031 | H66: 7.5630252 | I66: 7.2016461 | J66: 4.4088176 | K66: 5.1495017 | L66: 12.761506 | M66: 6.3451777 | N66: 7.1138211 | O66: 4.3824701 | P66: 5.5690073 | Q66: 3.9783002 | R66: 5.8287796 | S66: 5.7728119 | T66: 7.1017274 | U66: 6.0665362 | V66: 5.3097345 | W66: 6.2608696 | X66: 4.7222222 | Y66: 4.6544429 | Z66: 4.5454545 | AA66: 5.6338028 | AB66: 4.9848943 | AC66: 5.2005944 | AD66: 4.1907514 | AE66: 8.0188679 | AF66: 7.082153 | AG66: 4.0730337 | AH66: 0.25929127 | AI66: 2.7811366 | AJ66: 5.6856187 | AK66: 5.7432432 | AL66: 5.3097345 | AM66: 4.109589 | AN66: 6.1482821 | AO66: 6.8728522 | AP66: 4.9469965 | AQ66: 8.7102178 | AR66: 9.4370861 | AS66: 4.9319728 | AT66: 6.4798599 | AU66: #N/A | AV66: 0.19267823 | AW66: -10.183684 | AX66: 0.7253886 | AY66: 2.2339028 | AZ66: -0.77777778 | BA66: 1.1597938 | BB66: 11.816193 | BC66: 7.5892857 | BD66: 8.8582677 | BE66: 8.5062241 | BF66: 9.3065693 | BG66: 8.2746479 | BH66: 7.2657744 | BI66: 10.964912 | BJ66: 6.3953488 | BK66: 6.1461794 | BL66: 4.2836041 | BM66: #N/A | BN66: 6.875 | BO66: 3.6906854
A67: 41759 | B67: 6.1188811 | C67: 5.6105611 | D67: 7.755102 | E67: 8.1799591 | F67: 10.061602 | G67: 6.8493151 | H67: 8.3333333 | I67: 9.0534979 | J67: 6.2753036 | K67: 2.4630542 | L67: 9.9391481 | M67: 5.5137845 | N67: 7.1138211 | O67: 4.3737575 | P67: 5.5421687 | Q67: 3.7974684 | R67: 5.0359712 | S67: 4.7619048 | T67: 6.5420561 | U67: 4.4487427 | V67: 4.5454545 | W67: 5.5077453 | X67: 4.9861496 | Y67: 5.0704225 | Z67: 4.9399199 | AA67: 5.8098592 | AB67: 4.9848943 | AC67: 5.2005944 | AD67: 4.610951 | AE67: 8.0188679 | AF67: 7.082153 | AG67: 4.0730337 | AH67: 0 | AI67: 3.1400966 | AJ67: 5.6856187 | AK67: 5.7432432 | AL67: 4.7285464 | AM67: 3.5353535 | AN67: 6.1371841 | AO67: 6.6666667 | AP67: 5.2816901 | AQ67: 7.960199 | AR67: 9.0311987 | AS67: 4.2087542 | AT67: 6.4798599 | AU67: #N/A | AV67: -0.38535645 | AW67: -10.580856 | AX67: 0.10351967 | AY67: 2.621232 | AZ67: -0.22296544 | BA67: 1.7902813 | BB67: 12.121212 | BC67: 4.9944506 | BD67: 8.8582677 | BE67: 8.5062241 | BF67: 9.3065693 | BG67: 8.5814361 | BH67: 7.9847909 | BI67: 10.380117 | BJ67: 6.5637066 | BK67: 5.5829228 | BL67: 4.4052863 | BM67: #N/A | BN67: 7.2765073 | BO67: 3.6906854
A68: 41790 | B68: 6.4798599 | C68: 5.601318 | D68: 8.7755102 | E68: 9.202454 | F68: 10.224949 | G68: 8.2352941 | H68: 8.2474227 | I68: 9.8159509 | J68: 4.0322581 | K68: 5.6027165 | L68: 13.496933 | M68: 6.2656642 | N68: 7.9268293 | O68: 5.1792829 | P68: 6.0240964 | Q68: 4.7101449 | R68: 5.1971326 | S68: 5.3016453 | T68: 8.2242991 | U68: 4.8262548 | V68: 4.5217391 | W68: 5.6798623 | X68: 5.401662 | Y68: 5.2039381 | Z68: 5.0666667 | AA68: 5.8098592 | AB68: 4.9848943 | AC68: 5.2005944 | AD68: 6.0781476 | AE68: 8.0188679 | AF68: 7.082153 | AG68: 3.6465638 | AH68: -0.94664372 | AI68: 3.5024155 | AJ68: 5.3511706 | AK68: 5.7432432 | AL68: 4.7120419 | AM68: 3.1719533 | AN68: 6.1371841 | AO68: 8.9160839 | AP68: 6.1403509 | AQ68: 12.326389 | AR68: 14.26087 | AS68: 4.9069374 | AT68: 6.6666667 | AU68: #N/A | AV68: -0.48169557 | AW68: -11.181493 | AX68: 0.10351967 | AY68: 2.7486911 | AZ68: -0.33333333 | BA68: 2.173913 | BB68: 12.364425 | BC68: 2.2075055 | BD68: 8.8582677 | BE68: 8.5062241 | BF68: 9.3065693 | BG68: 8.173913 | BH68: 7.5471698 | BI68: 9.9270073 | BJ68: 6.9632495 | BK68: 6.7768595 | BL68: 4.4052863 | BM68: #N/A | BN68: 7.2765073 | BO68: 3.6906854
A69: 41820 | B69: 6.8181818 | C69: 5.5737705 | D69: 8.7755102 | E69: 9.406953 | F69: 10.633947 | G69: 8.8757396 | H69: 8.4536082 | I69: 9.9391481 | J69: 3.2064128 | K69: 1.5384615 | L69: 12.164948 | M69: 6.234414 | N69: 7 | O69: 4.518664 | P69: 6.9047619 | Q69: 3.9355993 | R69: 5.5655296 | S69: 5.6776557 | T69: 9.0225564 | U69: 4.2307692 | V69: 5.4101222 | W69: 5.1546392 | X69: 5.1104972 | Y69: 5.3370787 | Z69: 5.0599201 | AA69: 5.7591623 | AB69: 5.2083333 | AC69: 4.9780381 | AD69: 6.0693642 | AE69: 8.0188679 | AF69: 7.082153 | AG69: 4.0277778 | AH69: 0.7860262 | AI69: 4.7330097 | AJ69: 5.2459016 | AK69: 5.7755776 | AL69: 5.2447552 | AM69: 4.5226131 | AN69: 6.1371841 | AO69: 8.5365854 | AP69: 6.1403509 | AQ69: 11.343805 | AR69: 13.309982 | AS69: 4.8739496 | AT69: 6.5404475 | AU69: #N/A | AV69: -1.0536398 | AW69: -12.503443 | AX69: -0.51440329 | AY69: 2.745098 | AZ69: 0.22246941 | BA69: 1.9132653 | BB69: 10.920771 | BC69: 4.638009 | BD69: 8.8582677 | BE69: 8.5062241 | BF69: 9.3065693 | BG69: 8.3333333 | BH69: 7.8651685 | BI69: 10.014728 | BJ69: 6.9632495 | BK69: 6.5681445 | BL69: 4.4052863 | BM69: #N/A | BN69: 7.5 | BO69: 3.6906854
A70: 41851 | B70: 6.4013841 | C70: 5.7096248 | D70: 8.7755102 | E70: 8.9795918 | F70: 8.7221095 | G70: 8.6956522 | H70: 8.0246914 | I70: 11.764706 | J70: 2.6262626 | K70: 2.2608696 | L70: 11.909651 | M70: 7.518797 | N70: 8.8176353 | O70: 6.5346535 | P70: 9.8321343 | Q70: 5.4054054 | R70: 5.8823529 | S70: 5.2919708 | T70: 8.5820896 | U70: 3.256705 | V70: 4.8695652 | W70: 7.2758037 | X70: 5.0894085 | Y70: 5.4621849 | Z70: 5.0531915 | AA70: 5.9931507 | AB70: 5.2083333 | AC70: 4.9780381 | AD70: 6.2138728 | AE70: 8.2969432 | AF70: 6.8783069 | AG70: 3.8888889 | AH70: 0.78534031 | AI70: 3.9903265 | AJ70: 5.2459016 | AK70: 5.7755776 | AL70: 5.7692308 | AM70: 5.1839465 | AN70: 6.1371841 | AO70: 6.8027211 | AP70: 5.5846422 | AQ70: 7.615894 | AR70: 8.3606557 | AS70: 5.5649241 | AT70: 6.7125645 | AU70: #N/A | AV70: -1.4312977 | AW70: -11.847947 | AX70: -0.82051282 | AY70: 3.27654 | AZ70: 0.44593088 | BA70: 2.2959184 | BB70: 13.015184 | BC70: 5.8285714 | BD70: 8.8582677 | BE70: 8.5062241 | BF70: 9.3065693 | BG70: 8.1034483 | BH70: 8.2242991 | BI70: 8.0058224 | BJ70: 6.9364162 | BK70: 6.3934426 | BL70: 5.0872093 | BM70: #N/A | BN70: 7.9166667 | BO70: 4.5375218
A71: 41882 | B71: 6.5517241 | C71: 5.7003257 | D71: 9.3495935 | E71: 9.5723014 | F71: 7.6305221 | G71: 9.9009901 | H71: 7.1574642 | I71: 12.701613 | J71: 0.99403579 | K71: 2.4347826 | L71: 13.900415 | M71: 8.5 | N71: 9.9800399 | O71: 6.8897638 | P71: 10.613208 | Q71: 5.5755396 | R71: 6.0606061 | S71: 5.6672761 | T71: 8.7850467 | U71: 5.4158607 | V71: 4.3327556 | W71: 7.7441077 | X71: 5.3278689 | Y71: 5.4166667 | Z71: 5.0131926 | AA71: 5.982906 | AB71: 5.2083333 | AC71: 4.9780381 | AD71: 5.730659 | AE71: 8.7336245 | AF71: 7.1428571 | AG71: 3.6111111 | AH71: -0.43440487 | AI71: 4.0914561 | AJ71: 5.0819672 | AK71: 5.7755776 | AL71: 5.4195804 | AM71: 4.6901173 | AN71: 6.1371841 | AO71: 6.0504202 | AP71: 6.2608696 | AQ71: 5.3484603 | AR71: 5.76 | AS71: 4.8414023 | AT71: 6.7125645 | AU71: #N/A | AV71: -1.6159696 | AW71: -11.61545 | AX71: -1.0214505 | AY71: 3.2679739 | AZ71: 1.1173184 | BA71: 2.2959184 | BB71: 10.660981 | BC71: 5.3631285 | BD71: 8.8582677 | BE71: 8.5062241 | BF71: 9.3065693 | BG71: 8.5910653 | BH71: 8.9385475 | BI71: 7.4605452 | BJ71: 6.7307692 | BK71: 7.5286416 | BL71: 5.0872093 | BM71: #N/A | BN71: 7.9166667 | BO71: 4.3554007
A72: 41912 | B72: 6.185567 | C72: 5.6726094 | D72: 8.6868687 | E72: 8.8888889 | F72: 5.9405941 | G72: 9.4674556 | H72: 8.5714286 | I72: 12.8 | J72: -0.98425197 | K72: 1.0291595 | L72: 12.936345 | M72: 8.478803 | N72: 9.3253968 | O72: 5.2529183 | P72: 9.3240093 | Q72: 4.0925267 | R72: 6.0390764 | S72: 5.2823315 | T72: 8.3643123 | U72: 3.2380952 | V72: 5.0347222 | W72: 7.9124579 | X72: 5.5782313 | Y72: 5.5172414 | Z72: 5.3876478 | AA72: 5.9322034 | AB72: 5.1470588 | AC72: 4.7756874 | AD72: 5.5634807 | AE72: 8.7336245 | AF72: 7.1428571 | AG72: 3.1636864 | AH72: -1.3888889 | AI72: 3.2181168 | AJ72: 4.2003231 | AK72: 4.8780488 | AL72: 5.7591623 | AM72: 5.1752922 | AN72: 6.1371841 | AO72: 4.1946309 | AP72: 6.0658579 | AQ72: 1.6233766 | AR72: 1.2861736 | AS72: 3.814262 | AT72: 7.5342466 | AU72: #N/A | AV72: -1.3358779 | AW72: -12.677658 | AX72: -0.71721311 | AY72: 2.8645833 | AZ72: 0.78125 | BA72: 2.1656051 | BB72: 9.6842105 | BC72: 2.5027203 | BD72: 8.8582677 | BE72: 8.5062241 | BF72: 9.3065693 | BG72: 8.8737201 | BH72: 9.2936803 | BI72: 7.9320113 | BJ72: 6.7307692 | BK72: 6.0162602 | BL72: 5.0872093 | BM72: #N/A | BN72: 7.9166667 | BO72: 4.3554007
A73: 41943 | B73: 5.8219178 | C73: 5.6634304 | D73: 7.8 | E73: 8.0160321 | F73: 5.1282051 | G73: 9.375 | H73: 7.5356415 | I73: 12.57485 | J73: -1.7786561 | K73: 3.6206897 | L73: 8.7649402 | M73: 8.7719298 | N73: 8.7548638 | O73: 5.4368932 | P73: 8.1585082 | Q73: 4.2402827 | R73: 6.5255732 | S73: 6.1261261 | T73: 9.5327103 | U73: 3.2258065 | V73: 5.982906 | W73: 7.9124579 | X73: 5.6910569 | Y73: 5.922865 | Z73: 5.7667104 | AA73: 5.9322034 | AB73: 5.1470588 | AC73: 4.7756874 | AD73: 5.1282051 | AE73: 8.7336245 | AF73: 7.1428571 | AG73: 2.4657534 | AH73: -2.7681661 | AI73: 3.0989273 | AJ73: 4.0257649 | AK73: 4.8780488 | AL73: 5.7391304 | AM73: 5.8139535 | AN73: 6.1371841 | AO73: 4.7058824 | AP73: 5.6701031 | AQ73: 2.7960526 | AR73: 2.4429967 | AS73: 3.807947 | AT73: 8.034188 | AU73: #N/A | AV73: -1.9924099 | AW73: -12.759815 | AX73: -1.3238289 | AY73: 2.8645833 | AZ73: 0.44692737 | BA73: 2.1656051 | BB73: 10.570825 | BC73: 2.9001074 | BD73: 8.8582677 | BE73: 8.5062241 | BF73: 9.3065693 | BG73: 8.8435374 | BH73: 8.9053803 | BI73: 9.1292135 | BJ73: 6.7307692 | BK73: 5.4750403 | BL73: 5.0872093 | BM73: #N/A | BN73: 7.9166667 | BO73: 4.3554007
A74: 41973 | B74: 5.6410256 | C74: 5.815832 | D74: 7.5396825 | E74: 7.7380952 | F74: 5.3359684 | G74: 9.2485549 | H74: 8.3333333 | I74: 12.723658 | J74: -1.7681729 | K74: 11.538462 | L74: 5.8365759 | M74: 7.960199 | N74: 8.2851638 | O74: 5.0387597 | P74: 8.3140878 | Q74: 3.7168142 | R74: 7.6241135 | S74: 7.4275362 | T74: 9.9437148 | U74: 5.4158607 | V74: 7.008547 | W74: 8.6294416 | X74: 6.2246279 | Y74: 6.6024759 | Z74: 5.613577 | AA74: 5.9322034 | AB74: 5.1470588 | AC74: 4.7756874 | AD74: 5.4131054 | AE74: 8.7336245 | AF74: 7.1428571 | AG74: 2.1887825 | AH74: -3.1114952 | AI74: 2.1251476 | AJ74: 4.0257649 | AK74: 4.8780488 | AL74: 5.9233449 | AM74: 5.8139535 | AN74: 6.1371841 | AO74: 4.2301184 | AP74: 5.2991453 | AQ74: 1.6722408 | AR74: 1.1647255 | AS74: 3.9735099 | AT74: 7.8767123 | AU74: #N/A | AV74: -0.86372361 | AW74: -13.746004 | AX74: -0.30864198 | AY74: 2.7272727 | AZ74: 0.66889632 | BA74: 2.1656051 | BB74: 10.714286 | BC74: 2.1231423 | BD74: 8.8582677 | BE74: 8.5062241 | BF74: 9.3065693 | BG74: 8.9225589 | BH74: 9.0073529 | BI74: 9.4839609 | BJ74: 6.9230769 | BK74: 5.7877814 | BL74: 5.0872093 | BM74: #N/A | BN74: 7.9166667 | BO74: 4.3554007 | DL74: 5.27
A75: 42004 | B75: 5.4607509 | C75: 5.8064516 | D75: 7.1570577 | E75: 7.554672 | F75: 4.7337278 | G75: 9.2130518 | H75: 7.9754601 | I75: 12.5 | J75: -1.7716535 | K75: 9.6930533 | L75: 4.9603175 | M75: 8.2706767 | N75: 7.1428571 | O75: 4.6601942 | P75: 8.3140878 | Q75: 3.1971581 | R75: 7.6241135 | S75: 7.4275362 | T75: 11.005693 | U75: 5.2123552 | V75: 6.6439523 | W75: 8.2491582 | X75: 6.1994609 | Y75: 6.5753425 | Z75: 5.7441253 | AA75: 5.7239057 | AB75: 4.9490539 | AC75: 4.8780488 | AD75: 5.7142857 | AE75: 8.7336245 | AF75: 7.1428571 | AG75: 2.1857923 | AH75: -2.530541 | AI75: 1.902497 | AJ75: 4.0064103 | AK75: 5.4927302 | AL75: 5.5749129 | AM75: 5 | AN75: 6.1371841 | AO75: 1.8487395 | AP75: 5.6410256 | AQ75: -3.4710744 | AR75: -5.2631579 | AS75: 4.3117745 | AT75: 6.5767285 | AU75: #N/A | AV75: -1.6330451 | AW75: -12.559382 | AX75: -1.2345679 | AY75: 2.9908973 | AZ75: 0.44792833 | BA75: 2.5477707 | BB75: 11.297071 | BC75: 3.8461538 | BD75: 8.8582677 | BE75: 8.5062241 | BF75: 9.3065693 | BG75: 8.5284281 | BH75: 8.7272727 | BI75: 8.356546 | BJ75: 7.1153846 | BK75: 5.6179775 | BL75: 5.0872093 | BM75: #N/A | BN75: 7.9166667 | BO75: 4.3554007
A76: 42035 | B76: 4.5762712 | C76: 5.7877814 | D76: 6.6536204 | E76: 6.8493151 | F76: 4.6966732 | G76: 8.8512241 | H76: 7.2 | I76: 11.83432 | J76: -0.78895464 | K76: 7.52 | L76: 0.95419847 | M76: 8.4367246 | N76: 6.9811321 | O76: 4.1984733 | P76: 8.2568807 | Q76: 2.7826087 | R76: 7.5837743 | S76: 7.0017953 | T76: 10.074627 | U76: 4.0076336 | V76: 6.9491525 | W76: 8.7986464 | X76: 6.0402685 | Y76: 6.4120055 | Z76: 5.4474708 | AA76: 5.7239057 | AB76: 4.9490539 | AC76: 4.8780488 | AD76: 5.6577086 | AE76: 8.7336245 | AF76: 7.1428571 | AG76: 2.4590164 | AH76: -2.8045574 | AI76: 2.1301775 | AJ76: 4.32 | AK76: 5.4927302 | AL76: 5.9233449 | AM76: 5.8139535 | AN76: 6.1371841 | AO76: -2.6533997 | AP76: 6.292517 | AQ76: -12.924071 | AR76: -17.703349 | AS76: 4.2692939 | AT76: 6.2394604 | AU76: #N/A | AV76: -1.6330451 | AW76: -12.057588 | AX76: -1.1316872 | AY76: 2.4484536 | AZ76: 0.11173184 | BA76: 3.4394904 | BB76: 7 | BC76: 0.94637224 | BD76: 8.8582677 | BE76: 8.5062241 | BF76: 9.3065693 | BG76: 7.2727273 | BH76: 8.1374322 | BI76: 4.8582996 | BJ76: 7.2796935 | BK76: 6.4102564 | BL76: 3.8243626 | BM76: #N/A | BN76: 7.9166667 | BO76: 5.7823129
A77: 42063 | B77: 4.0268456 | C77: 5.7142857 | D77: 6.4202335 | E77: 6.614786 | F77: 4.0307102 | G77: 8.8679245 | H77: 7.8895464 | I77: 11.741683 | J77: -0.7797271 | K77: 0.32258065 | L77: 1.9157088 | M77: 8.6633663 | N77: 7.9847909 | O77: 5.1724138 | P77: 8.6757991 | Q77: 3.6713287 | R77: 8.0701754 | S77: 8.2437276 | T77: 10.634328 | U77: 4.3977055 | V77: 8.6003373 | W77: 8.4459459 | X77: 5.7333333 | Y77: 5.9539919 | Z77: 5.2767053 | AA77: 5.5462185 | AB77: 4.9490539 | AC77: 4.8780488 | AD77: 5.0420168 | AE77: 8.7336245 | AF77: 7.1428571 | AG77: 2.3129252 | AH77: -3.8095238 | AI77: 2.7090695 | AJ77: 4.64 | AK77: 5.4927302 | AL77: 5.7239057 | AM77: 5.2805281 | AN77: 6.4735945 | AO77: -6.372549 | AP77: 5.9121622 | AQ77: -20.597484 | AR77: -26.780186 | AS77: 3.2520325 | AT77: 6.0606061 | AU77: #N/A | AV77: -1.6330451 | AW77: -13.107379 | AX77: -1.1316872 | AY77: 2.7061856 | AZ77: 0 | BA77: 3.3121019 | BB77: 8.6 | BC77: 3.2734952 | BD77: 8.8582677 | BE77: 8.5062241 | BF77: 9.3065693 | BG77: 7.0723684 | BH77: 8.318264 | BI77: 3.4482759 | BJ77: 7.678245 | BK77: 7.2115385 | BL77: 3.8243626 | BM77: #N/A | BN77: 8.5769981 | BO77: 5.7823129
A78: 42094 | B78: 3.9669421 | C78: 5.6426332 | D78: 5.950096 | E78: 5.7471264 | F78: 3.5984848 | G78: 8.411215 | H78: 7.03125 | I78: 9.596929 | J78: -0.38387716 | K78: 1.2638231 | L78: 0.37105751 | M78: 7.875895 | N78: 8.1593928 | O78: 4.7709924 | P78: 8.7155963 | Q78: 3.4782609 | R78: 8.9500861 | S78: 8.9788732 | T78: 8.9605735 | U78: 3.5055351 | V78: 10.588235 | W78: 8.5106383 | X78: 5.8355438 | Y78: 6.06469 | Z78: 5.1150895 | AA78: 5.6666667 | AB78: 5.323741 | AC78: 4.8022599 | AD78: 4.2995839 | AE78: 8.7336245 | AF78: 7.1428571 | AG78: 2.0242915 | AH78: -4.4827586 | AI78: 2.7058824 | AJ78: 4.4303797 | AK78: 5.2715655 | AL78: 5.8823529 | AM78: 5.4276316 | AN78: 6.4735945 | AO78: -4.9839228 | AP78: 5.5555556 | AQ78: -16.33282 | AR78: -21.633888 | AS78: 5.1863857 | AT78: 3.9473684 | AU78: #N/A | AV78: -1.5384615 | AW78: -12.75188 | AX78: -1.1316872 | AY78: 2.3136247 | AZ78: 0.11198208 | BA78: 3.3121019 | BB78: 7.0450098 | BC78: 0 | BD78: 9.2224231 | BE78: 8.7954111 | BF78: 9.8497496 | BG78: 6.8292683 | BH78: 6.9518717 | BI78: 5.4018445 | BJ78: 7.6502732 | BK78: 6.7292645 | BL78: 3.8243626 | BM78: #N/A | BN78: 8.5769981 | BO78: 5.7627119
A79: 42124 | B79: 4.6128501 | C79: 5.625 | D79: 4.9242424 | E79: 4.9149338 | F79: 2.4253731 | G79: 6.4102564 | H79: 5.7692308 | I79: 8.490566 | J79: -2.2857143 | K79: 7.6923077 | L79: 2.2140221 | M79: 8.7885986 | N79: 6.2618596 | O79: 5.3333333 | P79: 8.9041096 | Q79: 4.1811847 | R79: 9.5890411 | S79: 9.7902098 | T79: 8.5964912 | U79: 4.0740741 | V79: 11.87291 | W79: 8.9722675 | X79: 5.5408971 | Y79: 5.7640751 | Z79: 4.9618321 | AA79: 5.4908486 | AB79: 5.323741 | AC79: 4.8022599 | AD79: 3.4435262 | AE79: 8.7336245 | AF79: 7.1428571 | AG79: 2.1592443 | AH79: -3.8062284 | AI79: 2.6932084 | AJ79: 4.5886076 | AK79: 5.2715655 | AL79: 6.0200669 | AM79: 5.3658537 | AN79: 6.462585 | AO79: -0.96153846 | AP79: 4.6822742 | AQ79: -7.5268817 | AR79: -10.692771 | AS79: 5.4927302 | AT79: 4.6052632 | AU79: #N/A | AV79: -0.96711799 | AW79: -12.503812 | AX79: -0.51706308 | AY79: 2.0434227 | AZ79: 0.22346369 | BA79: 2.3869347 | BB79: 5.7915058 | BC79: 1.2684989 | BD79: 9.2224231 | BE79: 8.7954111 | BF79: 9.8497496 | BG79: 5.6451613 | BH79: 6.3380282 | BI79: 3.7086093 | BJ79: 7.2463768 | BK79: 6.2208398 | BL79: 3.0942335 | BM79: #N/A | BN79: 8.1395349 | BO79: 5.7627119
A80: 42155 | B80: 4.6052632 | C80: 5.7722309 | D80: 4.6904315 | E80: 4.6816479 | F80: 3.7105751 | G80: 5.2536232 | H80: 7.4285714 | I80: 7.6350093 | J80: 0.58139535 | K80: 3.0546624 | L80: -1.4414414 | M80: 9.4339623 | N80: 7.1563089 | O80: 5.3030303 | P80: 8.6363636 | Q80: 4.3252595 | R80: 9.5400341 | S80: 9.7222222 | T80: 7.5993092 | U80: 5.1565378 | V80: 11.813644 | W80: 8.7947883 | X80: 5.2562418 | Y80: 5.6149733 | Z80: 4.822335 | AA80: 5.4908486 | AB80: 5.323741 | AC80: 4.8022599 | AD80: 2.8649386 | AE80: 8.7336245 | AF80: 7.1428571 | AG80: 2.5710419 | AH80: -3.4752389 | AI80: 3.1505251 | AJ80: 4.6031746 | AK80: 5.2715655 | AL80: 6.8333333 | AM80: 7.2815534 | AN80: 6.462585 | AO80: -0.64205457 | AP80: 4.1322314 | AQ80: -6.9551777 | AR80: -9.7412481 | AS80: 5.3225806 | AT80: 4.6052632 | AU80: #N/A | AV80: -0.38722168 | AW80: -12.806202 | AX80: 0 | AY80: 1.7834395 | AZ80: 0.11148272 | BA80: 2.0025031 | BB80: 7.1428571 | BC80: -2.699784 | BD80: 9.2224231 | BE80: 8.7954111 | BF80: 9.8497496 | BG80: 6.2700965 | BH80: 7.3684211 | BI80: 3.7184595 | BJ80: 7.4141049 | BK80: 6.0371517 | BL80: 3.0942335 | BM80: #N/A | BN80: 8.1395349 | BO80: 6.6101695
A81: 42185 | B81: 4.5826514 | C81: 5.4347826 | D81: 4.315197 | E81: 4.1121495 | F81: 3.142329 | G81: 5.2536232 | H81: 7.0342205 | I81: 6.8265683 | J81: 0.97087379 | K81: 4.040404 | L81: -1.4705882 | M81: 9.1549296 | N81: 5.7943925 | O81: 4.6992481 | P81: 6.6815145 | Q81: 3.7865749 | R81: 9.6938776 | S81: 10.051993 | T81: 7.2413793 | U81: 5.3505535 | V81: 11.754967 | W81: 9.3137255 | X81: 5.6504599 | Y81: 5.8666667 | Z81: 4.8162231 | AA81: 5.4455446 | AB81: 4.8090523 | AC81: 4.4630404 | AD81: 2.8610354 | AE81: 8.7336245 | AF81: 7.1428571 | AG81: 2.1361816 | AH81: -4.8526863 | AI81: 2.5492468 | AJ81: 4.6728972 | AK81: 5.1482059 | AL81: 6.1461794 | AM81: 5.7692308 | AN81: 6.462585 | AO81: 0.64205457 | AP81: 4.1322314 | AQ81: -2.9780564 | AR81: -4.9459042 | AS81: 4.9679487 | AT81: 3.0694669 | AU81: #N/A | AV81: -0.38722168 | AW81: -12.716399 | AX81: 0 | AY81: 1.9083969 | AZ81: 0.22197558 | BA81: 2.1276596 | BB81: 8.1081081 | BC81: -3.7837838 | BD81: 9.2224231 | BE81: 8.7954111 | BF81: 9.8497496 | BG81: 6.25 | BH81: 6.7708333 | BI81: 4.0160643 | BJ81: 7.2332731 | BK81: 5.5469954 | BL81: 3.0942335 | BM81: #N/A | BN81: 8.1395349 | BO81: 6.2711864
A82: 42216 | B82: 5.0406504 | C82: 5.2469136 | D82: 4.5028143 | E82: 4.3071161 | F82: 4.6641791 | G82: 5.2727273 | H82: 7.6190476 | I82: 5.0816697 | J82: 2.5590551 | K82: 2.3809524 | L82: -1.2844037 | M82: 8.1585082 | N82: 4.7882136 | O82: 3.9033457 | P82: 5.6768559 | Q82: 3.4188034 | R82: 8.9225589 | S82: 10.051993 | T82: 7.5601375 | U82: 6.3079777 | V82: 12.106136 | W82: 5.6782334 | X82: 5.6282723 | Y82: 5.7104914 | Z82: 5.3164557 | AA82: 6.4620355 | AB82: 4.8090523 | AC82: 4.4630404 | AD82: 2.4489796 | AE82: 10.080645 | AF82: 11.386139 | AG82: 2.1390374 | AH82: -5.1082251 | AI82: 2.7906977 | AJ82: 4.6728972 | AK82: 5.1482059 | AL82: 5.9504132 | AM82: 5.0874404 | AN82: 6.462585 | AO82: 0.95541401 | AP82: 4.1322314 | AQ82: -2.4615385 | AR82: -4.0847201 | AS82: 3.514377 | AT82: 2.9032258 | AU82: #N/A | AV82: -0.67763795 | AW82: -14.416116 | AX82: -0.10341262 | AY82: 2.1573604 | AZ82: 0.66592675 | BA82: 2.244389 | BB82: 6.7178503 | BC82: 0.43196544 | BD82: 9.2224231 | BE82: 8.7954111 | BF82: 9.8497496 | BG82: 5.9011164 | BH82: 6.7357513 | BI82: 4.1778976 | BJ82: 7.027027 | BK82: 5.238829 | BL82: 2.2130014 | BM82: #N/A | BN82: 8.1081081 | BO82: 5.8430718
A83: 42247 | B83: 4.5307443 | C83: 5.238829 | D83: 4.4609665 | E83: 4.4609665 | F83: 5.9701493 | G83: 5.045045 | H83: 8.2061069 | I83: 3.7567084 | J83: 5.7086614 | K83: 4.4142615 | L83: -2.3679417 | M83: 7.6036866 | N83: 4.3557169 | O83: 3.6832413 | P83: 4.0511727 | Q83: 3.7478705 | R83: 8.907563 | S83: 10.207612 | T83: 7.3883162 | U83: 6.0550459 | V83: 12.624585 | W83: 4.6875 | X83: 5.3177691 | Y83: 5.4018445 | Z83: 5.1507538 | AA83: 6.2903226 | AB83: 4.8090523 | AC83: 4.4630404 | AD83: 1.897019 | AE83: 9.6385542 | AF83: 11.111111 | AG83: 2.8150134 | AH83: -4.0139616 | AI83: 2.8901734 | AJ83: 4.8361934 | AK83: 5.1482059 | AL83: 6.3018242 | AM83: 6.08 | AN83: 6.462585 | AO83: -0.79239303 | AP83: 3.9279869 | AQ83: -5.2307692 | AR83: -7.5642965 | AS83: 3.343949 | AT83: 2.2580645 | AU83: #N/A | AV83: -0.77294686 | AW83: -14.673046 | AX83: -0.20639835 | AY83: 2.278481 | AZ83: 0.33149171 | BA83: 2.244389 | BB83: 8.477842 | BC83: 0 | BD83: 9.2224231 | BE83: 8.7954111 | BF83: 9.8497496 | BG83: 5.5379747 | BH83: 5.982906 | BI83: 3.7383178 | BJ83: 7.027027 | BK83: 4.56621 | BL83: 2.2130014 | BM83: #N/A | BN83: 8.1081081 | BO83: 5.509182
A84: 42277 | B84: 4.5307443 | C84: 5.2147239 | D84: 4.4609665 | E84: 4.2671614 | F84: 6.3551402 | G84: 4.8648649 | H84: 7.1428571 | I84: 3.0141844 | J84: 6.9582505 | K84: 1.3582343 | L84: -1.6363636 | M84: 7.816092 | N84: 4.3557169 | O84: 4.0665434 | P84: 4.4776119 | Q84: 3.5897436 | R84: 8.5427136 | S84: 10.380623 | T84: 7.3756432 | U84: 6.6420664 | V84: 12.231405 | W84: 4.524181 | X84: 4.8969072 | Y84: 5.0980392 | Z84: 4.4887781 | AA84: 6.24 | AB84: 4.8951049 | AC84: 4.9723757 | AD84: 1.8918919 | AE84: 9.6385542 | AF84: 11.111111 | AG84: 2.6666667 | AH84: -3.5211268 | AI84: 2.3094688 | AJ84: 5.1162791 | AK84: 5.4263566 | AL84: 5.7755776 | AM84: 5.3968254 | AN84: 6.462585 | AO84: -0.80515298 | AP84: 3.9215686 | AQ84: -5.7507987 | AR84: -8.2539683 | AS84: 3.8338658 | AT84: 1.910828 | AU84: #N/A | AV84: -0.67698259 | AW84: -13.151042 | AX84: -0.20639835 | AY84: 2.1518987 | AZ84: 0.22148394 | BA84: 2.244389 | BB84: 9.0211132 | BC84: -0.31847134 | BD84: 9.2224231 | BE84: 8.7954111 | BF84: 9.8497496 | BG84: 4.8589342 | BH84: 5.6122449 | BI84: 3.4120735 | BJ84: 7.027027 | BK84: 5.3680982 | BL84: 2.2130014 | BM84: #N/A | BN84: 7.9150579 | BO84: 5.509182
A85: 42308 | B85: 4.6925566 | C85: 5.2067381 | D85: 4.8237477 | E85: 4.8237477 | F85: 7.1294559 | G85: 4.2857143 | H85: 8.5227273 | I85: 3.0141844 | J85: 10.261569 | K85: -0.16638935 | L85: 0.54945055 | M85: 8.7557604 | N85: 3.2200358 | O85: 3.8674033 | P85: 5.8189655 | Q85: 3.220339 | R85: 7.4503311 | S85: 8.4889643 | T85: 6.8259386 | U85: 6.8014706 | V85: 9.516129 | W85: 4.3681747 | X85: 4.7435897 | Y85: 4.9414824 | Z85: 4.2131351 | AA85: 6.24 | AB85: 4.8951049 | AC85: 4.9723757 | AD85: 1.897019 | AE85: 9.6385542 | AF85: 11.111111 | AG85: 3.0748663 | AH85: -2.1352313 | AI85: 3.1213873 | AJ85: 4.7987616 | AK85: 5.4263566 | AL85: 5.9210526 | AM85: 5.1805338 | AN85: 6.462585 | AO85: -0.64205457 | AP85: 4.3902439 | AQ85: -5.44 | AR85: -7.9491256 | AS85: 3.6682616 | AT85: 1.5822785 | AU85: #N/A | AV85: -0.67763795 | AW85: -12.475182 | AX85: -0.20639835 | AY85: 2.7848101 | AZ85: 0.77864294 | BA85: 3.117207 | BB85: 9.3690249 | BC85: -0.52192067 | BD85: 9.2224231 | BE85: 8.7954111 | BF85: 9.8497496 | BG85: 5.3125 | BH85: 6.3032368 | BI85: 2.3166023 | BJ85: 7.027027 | BK85: 4.8854962 | BL85: 2.6279391 | BM85: #N/A | BN85: 7.9150579 | BO85: 5.509182
A86: 42338 | B86: 4.8543689 | C86: 5.0381679 | D86: 4.797048 | E86: 4.7882136 | F86: 7.3170732 | G86: 4.0564374 | H86: 6.9418386 | I86: 1.9400353 | J86: 11.4 | K86: -5.9970015 | L86: 2.2058824 | M86: 8.7557604 | N86: 3.5587189 | O86: 4.0590406 | P86: 5.3304904 | Q86: 3.7542662 | R86: 7.0840198 | S86: 7.925801 | T86: 6.6552901 | U86: 7.1559633 | V86: 8.6261981 | W86: 4.6728972 | X86: 4.4585987 | Y86: 4.516129 | Z86: 3.9555006 | AA86: 6.24 | AB86: 4.8951049 | AC86: 4.9723757 | AD86: 1.4864865 | AE86: 9.6385542 | AF86: 11.111111 | AG86: 3.2128514 | AH86: -2.1409456 | AI86: 3.583815 | AJ86: 4.7987616 | AK86: 5.4263566 | AL86: 5.7565789 | AM86: 4.866562 | AN86: 6.462585 | AO86: 0 | AP86: 4.2207792 | AQ86: -4.1118421 | AR86: -6.5789474 | AS86: 3.9808917 | AT86: 2.0634921 | AU86: #N/A | AV86: -0.67763795 | AW86: -11.489218 | AX86: -0.20639835 | AY86: 3.1605563 | AZ86: 1.1074197 | BA86: 3.117207 | BB86: 8.5388994 | BC86: 1.7671518 | BD86: 9.2224231 | BE86: 8.7954111 | BF86: 9.8497496 | BG86: 5.2550232 | BH86: 5.3962901 | BI86: 4.7133758 | BJ86: 6.8345324 | BK86: 3.9513678 | BL86: 2.6279391 | BM86: #N/A | BN86: 7.9150579 | BO86: 5.509182
...

Sheet sub
A1: month | B1: hinfl | C1: coreinfl | D1: cerealprod | E1: meat | F1: fish_seafood | G1: milk_dairy_eggs | H1: oil_fats | I1: fruit_nuts | J1: veggies | K1: sugar_dess | L1: other_food | M1: hot_bev | N1: cold_bev | O1: spirits | P1: wine | Q1: beer | R1: tobacco | S1: clothing | T1: footwear | U1: rentals | V1: OER | W1: main_repairs | X1: water_sup_serv | Y1: electr_ofuels | Z1: furn_carp | AA1: app_table_equip | AB1: gs_for_housemain | AC1: med_healthpro | AD1: health_serv | AE1: purch_vehicle | AF1: fuel | AG1: other_op_pers_trans_equip | AH1: pass_trans_serv | AI1: inf_com_equip | AJ1: info_com_serv | AK1: recr_goods_gardnprod | AL1: recr_cult_serv | AM1: news_book_stat | AN1: pack_hol | AO1: prim_sec_edu | AP1: tert_edu | AQ1: restaurants | AR1: accom_serv | AS1: pers_care | AT1: other_serv | AU1: insurance | AV1: fin_serv
A2: 39844 | B2: 8.1145585 | C2: 7.1274298 | D2: 27.777778 | E2: 7.8740157 | F2: 19.207317 | G2: 14.825581 | H2: 30.81571 | I2: 6.4516129 | J2: 19.005848 | K2: 13.00813 | L2: 18.209877 | M2: 23.371648 | N2: 8.9974293 | O2: 12.790698 | P2: 6.9892473 | Q2: 6.8870523 | R2: 12.849162 | S2: 4.1946309 | T2: 3.1626506 | U2: 7.8 | V2: 6.9811321 | W2: 16.28866 | X2: 4.9295775 | Y2: 30.985915 | Z2: 0.31397174 | AA2: 10.773481 | AB2: 8.2568807 | AC2: 7.5862069 | AD2: 7.5418994 | AE2: 1.0909091 | AF2: -20.639535 | AG2: 12.686567 | AH2: 17.032967 | AI2: -5.0985859 | AJ2: 1.4084507 | AK2: 10.176991 | AL2: 5.1282051 | AM2: 9.0909091 | AO2: 7.3943662 | AP2: 6.8047337 | AQ2: 12.99435 | AR2: 13.948498 | AS2: 12.068966 | AT2: 19.467213 | AU2: 6.3694268 | AV2: 17.142857
A3: 39872 | B3: 8.2938389 | C3: 7.9569892 | D3: 23.952096 | E3: 9.8143236 | F3: 19.877676 | G3: 13.832853 | H3: 25.443787 | I3: 8.8495575 | J3: 18.823529 | K3: 13.414634 | L3: 18.82716 | M3: 23.371648 | N3: 13.589744 | O3: 11.111111 | P3: 6.9518717 | Q3: 5.9139785 | R3: 14.24581 | S3: 5.0251256 | T3: 3.6144578 | U3: 7.8 | V3: 6.9811321 | W3: 16.632444 | X3: 4.9295775 | Y3: 30.28169 | Z3: 1.2628256 | AA3: 14.623955 | AB3: 8.9449541 | AC3: 7.816092 | AD3: 10.12987 | AE3: 2.003643 | AF3: -13.920455 | AG3: 14.179104 | AH3: 15.531335 | AI3: -5.6605671 | AJ3: 1.4084507 | AK3: 10.706402 | AL3: 6.5934066 | AM3: 11.620795 | AO3: 7.3943662 | AP3: 6.8047337 | AQ3: 13.202247 | AR3: 13.742072 | AS3: 13.333333 | AT3: 19.467213 | AU3: 7.9027356 | AV3: 17.142857
A4: 39903 | B4: 8.411215 | C4: 8.0679406 | D4: 20.05814 | E4: 10.904255 | F4: 20.743034 | G4: 12.290503 | H4: 11.924119 | I4: 12.975391 | J4: 18.452381 | K4: 15.447154 | L4: 16.86747 | M4: 26.61597 | N4: 9.6296296 | O4: 10.242588 | P4: 8.616188 | Q4: 8.0939948 | R4: 13.56383 | S4: 5.1752922 | T4: 3.7593985 | U4: 6.640625 | V4: 5.5350554 | W4: 17.525773 | X4: 4.9295775 | Y4: 30.28169 | Z4: 1.8297534 | AA4: 14.876033 | AB4: 9.0293454 | AC4: 13.47032 | AD4: 10.12987 | AE4: 2.1857923 | AF4: -14.736842 | AG4: 14.59854 | AH4: 13.821138 | AI4: -5.1412315 | AJ4: 1.4084507 | AK4: 12.513843 | AL4: 19.926874 | AM4: 12.765957 | AO4: 11.803279 | AP4: 8.5872576 | AQ4: 12.777778 | AR4: 14.579055 | AS4: 15.498938 | AT4: 19.467213 | AU4: 7.2507553 | AV4: 19.480519
A5: 39933 | B5: 8.372093 | C5: 8.2627119 | D5: 17.714286 | E5: 10.61008 | F5: 16.071429 | G5: 12.672176 | H5: 1.2626263 | I5: 12.337662 | J5: 17.888563 | K5: 16.465863 | L5: 17.313433 | M5: 31.320755 | N5: 9.3137255 | O5: 10.106383 | P5: 9.0673575 | Q5: 8.3550914 | R5: 13.492063 | S5: 5.6761269 | T5: 4.0540541 | U5: 6.640625 | V5: 5.5350554 | W5: 16.938776 | X5: 4.9295775 | Y5: 29.370629 | Z5: 0.078369906 | AA5: 16.968011 | AB5: 8.5201794 | AC5: 15.525114 | AD5: 10.12987 | AE5: 2.919708 | AF5: -17.274939 | AG5: 14.319809 | AH5: 15.068493 | AI5: -6.395112 | AJ5: 1.9586507 | AK5: 12.074643 | AL5: 21.195652 | AM5: 12.5 | AO5: 11.803279 | AP5: 8.5872576 | AQ5: 13.498623 | AR5: 13.963039 | AS5: 15.611814 | AT5: 17.303823 | AU5: 7.2507553 | AV5: 19.480519
A6: 39964 | B6: 8.0831409 | C6: 8.4566596 | D6: 10.483871 | E6: 10.23622 | F6: 13.953488 | G6: 12.84153 | H6: -3.4398034 | I6: 15.124153 | J6: 17.44186 | K6: 16.205534 | L6: 17.595308 | M6: 33.082707 | N6: 9.7799511 | O6: 10.344828 | P6: 9.0439276 | Q6: 8.0729167 | R6: 13.456464 | S6: 5.4908486 | T6: 3.742515 | U6: 6.640625 | V6: 5.5350554 | W6: 15 | X6: 4.9295775 | Y6: 30.28169 | Z6: 0.94711918 | AA6: 16 | AB6: 8.7053571 | AC6: 13.963964 | AD6: 10.649351 | AE6: 4.9541284 | AF6: -22.425629 | AG6: 13.711584 | AH6: 14.402174 | AI6: -7.6720648 | AJ6: 1.9586507 | AK6: 11.555076 | AL6: 20.976492 | AM6: 8.0229226 | AO6: 11.803279 | AP6: 8.5872576 | AQ6: 12.5 | AR6: 13.496933 | AS6: 15.932914 | AT6: 17.303823 | AU6: 7.2507553 | AV6: 19.480519
A7: 39994 | B7: 7.0615034 | C7: 7.7405858 | D7: 5.9278351 | E7: 8.5492228 | F7: 11.396011 | G7: 13.079019 | H7: -7.1599045 | I7: 10.185185 | J7: 17.251462 | K7: 14.84375 | L7: 15.229885 | M7: 27.797834 | N7: 9.5354523 | O7: 10.31746 | P7: 8.2051282 | Q7: 8.0729167 | R7: 13.157895 | S7: 5.1239669 | T7: 4.0419162 | U7: 5.7034221 | V7: 4.6931408 | W7: 13.333333 | X7: 4.9295775 | Y7: 28.472222 | Z7: 0.23622047 | AA7: 15.934066 | AB7: 8.7527352 | AC7: 13.199105 | AD7: 10.649351 | AE7: 4 | AF7: -24.94577 | AG7: 13.14554 | AH7: 4.4226044 | AI7: -10.365361 | AJ7: 1.9586507 | AK7: 11.410118 | AL7: 20.540541 | AM7: 7.0175439 | AO7: 11.803279 | AP7: 8.5872576 | AQ7: 11.2 | AR7: 13.877551 | AS7: 15.448852 | AT7: 17.303823 | AU7: 7.5528701 | AV7: 20
A8: 40025 | B8: 6.741573 | C8: 7.9002079 | D8: 3.8071066 | E8: 6.4267352 | F8: 11.267606 | G8: 11.229947 | H8: -8.9622642 | I8: 9.9307159 | J8: 14.534884 | K8: 12.21374 | L8: 13.202247 | M8: 26.33452 | N8: 11.407767 | O8: 9.7368421 | P8: 7.9081633 | Q8: 7.7922078 | R8: 15.789474 | S8: 5.4455446 | T8: 4.6407186 | U8: 5.7034221 | V8: 4.6931408 | W8: 13.009709 | X8: 9.0909091 | Y8: 27.272727 | Z8: 0.31695721 | AA8: 13.414634 | AB8: 8.9519651 | AC8: 11.699779 | AD8: 10.649351 | AE8: 2.8933092 | AF8: -26.166329 | AG8: 12.009238 | AH8: 3.1553398 | AI8: -10.53869 | AJ8: 1.9586507 | AK8: 11.948332 | AL8: 20.323741 | AM8: 7.2254335 | AO8: 11.803279 | AP8: 8.5872576 | AQ8: 10.875332 | AR8: 9.4674556 | AS8: 15.416667 | AT8: 14.990138 | AU8: 10.542169 | AV8: 17.884131
A9: 40056 | B9: 6.0267857 | C9: 7.6446281 | D9: 0.24630542 | E9: 5.3846154 | F9: 10.335196 | G9: 9.9737533 | H9: -11.36891 | I9: 11.08545 | J9: 13.276836 | K9: 10.074627 | L9: 13.687151 | M9: 20.608108 | N9: 11.594203 | O9: 9.9737533 | P9: 7.3417722 | Q9: 8.0729167 | R9: 18.575064 | S9: 5.0819672 | T9: 4.3090639 | U9: 5.7034221 | V9: 4.6931408 | W9: 8.3179298 | X9: 9.3959732 | Y9: 25.68306 | Z9: 0.078926598 | AA9: 11.27321 | AB9: 8.9324619 | AC9: 12.114537 | AD9: 10.649351 | AE9: 3.8112523 | AF9: -26.458333 | AG9: 12.240185 | AH9: 4.1769042 | AI9: -11.603705 | AJ9: 2.5668449 | AK9: 8.2291667 | AL9: 21.582734 | AM9: 5.3977273 | AO9: 11.803279 | AP9: 8.5872576 | AQ9: 10.55409 | AR9: 7.3643411 | AS9: 13.90593 | AT9: 14.990138 | AU9: 10.542169 | AV9: 16.129032
A10: 40086 | B10: 6.4444444 | C10: 6.9672131 | D10: -1.9323671 | E10: 4.0712468 | F10: 7.3569482 | G10: 7.1611253 | H10: -12.814645 | I10: 12.790698 | J10: 15.625 | K10: 10 | L10: 11.382114 | M10: 16.721311 | N10: 10.26253 | O10: 9.6605744 | P10: 7.0175439 | Q10: 6.9587629 | R10: 17.293233 | S10: 5.0653595 | T10: 4.4510386 | U10: 5.2631579 | V10: 4.8300537 | W10: 7.3126143 | X10: 9.3959732 | Y10: 25 | Z10: -0.94488189 | AA10: 9.5800525 | AB10: 8.3870968 | AC10: 12.77533 | AD10: 10.649351 | AE10: 2.7027027 | AF10: -17.225951 | AG10: 11.954023 | AH10: 1.4319809 | AI10: -11.657033 | AJ10: 2.1390374 | AK10: 6.5488565 | AL10: 19.929453 | AM10: 10.724638 | AO10: 11.803279 | AP10: 8.5872576 | AQ10: 11.081794 | AR10: 7.7071291 | AS10: 13.104839 | AT10: 14.09002 | AU10: 11.111111 | AV10: 7.8341014
A11: 40117 | B11: 6.4444444 | C11: 6.5306122 | D11: -2.173913 | E11: 4.0712468 | F11: 7.712766 | G11: 7.6923077 | H11: -13.926941 | I11: 13.519814 | J11: 16.576087 | K11: 8 | L11: 9.3085106 | M11: 14.469453 | N11: 11.217184 | O11: 9.6605744 | P11: 7.2864322 | Q11: 6.9587629 | R11: 16.41791 | S11: 5.2202284 | T11: 4.4444444 | U11: 5.2631579 | V11: 4.8300537 | W11: 6.3176895 | X11: 9.3959732 | Y11: 23.783784 | Z11: -0.94488189 | AA11: 8.5078534 | AB11: 7.7087794 | AC11: 12.77533 | AD11: 10.649351 | AE11: 2.7027027 | AF11: -18.894009 | AG11: 11.187215 | AH11: 1.4285714 | AI11: -15.456975 | AJ11: 2.1390374 | AK11: 4.6248715 | AL11: 19.929453 | AM11: 11.594203 | AO11: 11.803279 | AP11: 8.5872576 | AQ11: 7.6335878 | AR11: 8.3333333 | AS11: 11.84739 | AT11: 8.6556169 | AU11: 12.121212 | AV11: 7.8341014
A12: 40147 | B12: 6.2084257 | C12: 6.3136456 | D12: -2.8846154 | E12: 3.5264484 | F12: 5.974026 | G12: 9.0206186 | H12: -13.657407 | I12: 13.716814 | J12: 12.432432 | K12: 7.9710145 | L12: 8.7301587 | M12: 13.291139 | N12: 10.638298 | O12: 9.6605744 | P12: 7.5376884 | Q12: 6.9587629 | R12: 16.666667 | S12: 5.2202284 | T12: 4.5925926 | U12: 5.2631579 | V12: 4.8300537 | W12: 6.2836625 | X12: 9.3959732 | Y12: 24.324324 | Z12: -1.6483516 | AA12: 6.9100391 | AB12: 7.7087794 | AC12: 10.537634 | AD12: 10.649351 | AE12: 2.7075812 | AF12: -14.769976 | AG12: 10.909091 | AH12: 1.9047619 | AI12: -17.117603 | AJ12: 2.1390374 | AK12: 2.2132797 | AL12: 19.929453 | AM12: 6.5217391 | AO12: 11.803279 | AP12: 8.5872576 | AQ12: 7.5949367 | AR12: 7.7071291 | AS12: 10.27668 | AT12: 8.6556169 | AU12: 12.121212 | AV12: 7.8341014
A13: 40178 | B13: 6.4444444 | C13: 6.2880325 | D13: -3.125 | E13: 2.2277228 | F13: 4.6511628 | G13: 8.7403599 | H13: -13.657407 | I13: 10.315789 | J13: 6.2992126 | K13: 8.7912088 | L13: 7.6719577 | M13: 12.539185 | N13: 10.165485 | O13: 8.8311688 | P13: 7.5566751 | Q13: 6.9587629 | R13: 16.62531 | S13: 4.8701299 | T13: 4.4313146 | U13: 5.0092764 | V13: 4.0564374 | W13: 5.8928571 | X13: 9.3959732 | Y13: 23.655914 | Z13: -1.9685039 | AA13: 6.3802083 | AB13: 7.4152542 | AC13: 10.775862 | AD13: 10.649351 | AE13: 2.3423423 | AF13: 7.6696165 | AG13: 10.11236 | AH13: 0.46728972 | AI13: -19.52776 | AJ13: 2.1390374 | AK13: 3.058104 | AL13: 19.507909 | AM13: 11.142061 | AO13: 11.803279 | AP13: 8.5872576 | AQ13: 8.5642317 | AR13: 6.4272212 | AS13: 9.6078431 | AT13: 8.6556169 | AU13: 12.121212 | AV13: 7.8341014
... A60: 41608 | B60: 5.4054054 | C60: 5.2721088 | D60: 4.3298969 | E60: 0.19305019 | F60: 5.1282051 | G60: 7.9399142 | H60: 3.877551 | I60: 1.5280136 | J60: 4.8979592 | K60: 6.3492063 | L60: 5.4878049 | M60: 7.4441687 | N60: 4.4362292 | O60: 6.3872255 | P60: 3.4 | Q60: 8.9385475 | R60: 5.3475936 | S60: 3.4139403 | T60: 2.9569892 | U60: 4.7765794 | V60: 4.5385779 | W60: 4.3090639 | X60: 8.0188679 | Y60: 7.3863636 | Z60: -0.17256255 | AA60: 2.6666667 | AB60: 5.7921635 | AC60: 3.2590051 | AD60: 6.3339731 | AE60: 4.0925267 | AF60: 7.7060932 | AG60: 4.4982699 | AH60: 5.6057866 | AI60: -12.286515 | AJ60: 1.8867925 | AK60: 0.78651685 | AL60: 2.8833552 | AM60: 3.930131 | AO60: 9.0497738 | AP60: 8.9463221 | AQ60: 6.4579256 | AR60: 8.801214 | AS60: 5.7823129 | AT60: 2.8400598 | AU60: 8.5972851 | AV60: 5.5147059
A61: 41639 | B61: 5.3956835 | C61: 5.2631579 | D61: 4.3209877 | E61: 0 | F61: 5.1612903 | G61: 7.2340426 | H61: 3.0425963 | I61: 0.48701299 | J61: 5.4393305 | K61: 5.8355438 | L61: 5.4989817 | M61: 6.6502463 | N61: 3.3027523 | O61: 5.4 | P61: 4.8582996 | Q61: 9.310987 | R61: 5.8823529 | S61: 3.6931818 | T61: 2.8187919 | U61: 5.0458716 | V61: 4.6546547 | W61: 3.2448378 | X61: 8.0188679 | Y61: 7.082153 | Z61: -1.2068966 | AA61: 2.4360536 | AB61: 5.4054054 | AC61: 2.5641026 | AD61: 6.3339731 | AE61: 4.0925267 | AF61: 9.9457505 | AG61: 4.5060659 | AH61: 4.5855379 | AI61: -13.285273 | AJ61: 1.8867925 | AK61: 0.22446689 | AL61: 2.8833552 | AM61: 5.7522124 | AN61: 13.317191 | AO61: 9.0497738 | AP61: 8.9463221 | AQ61: 6.7961165 | AR61: 8.4592145 | AS61: 5.4145516 | AT61: 2.8400598 | AU61: 8.1081081 | AV61: 5.5147059
A62: 41670 | B62: 5.9245961 | C62: 5.2453469 | D62: 4.4989775 | E62: 1.7241379 | F62: 6.1571125 | G62: 6.7368421 | H62: 2.4242424 | I62: 2.4590164 | J62: 6.2880325 | K62: 5.7742782 | L62: 6.8548387 | M62: 5.5690073 | N62: 4.1666667 | O62: 6.1386139 | P62: 4.1749503 | Q62: 9.4619666 | R62: 5.1601423 | S62: 3.8243626 | T62: 3.2128514 | U62: 5.0458716 | V62: 4.6546547 | W62: 3.0612245 | X62: 8.0188679 | Y62: 7.082153 | Z62: -1.7226529 | AA62: 1.9300362 | AB62: 5.5743243 | AC62: 2.9059829 | AD62: 6.3339731 | AE62: 4.0707965 | AF62: 14.625229 | AG62: 5.3633218 | AH62: 4.5855379 | AI62: -13.335066 | AJ62: 1.8867925 | AK62: 0.22396417 | AL62: 2.7486911 | AM62: 12.612613 | AN62: 8.0681818 | AO62: 9.0497738 | AP62: 8.9463221 | AQ62: 6.7567568 | AR62: 9.2920354 | AS62: 5.0505051 | AT62: 4.2836041 | AU62: 8.1081081 | AV62: 3.3391916
A63: 41698 | B63: 5.8614565 | C63: 5.3511706 | D63: 7.4226804 | E63: 3.1128405 | F63: 7.4152542 | G63: 6.2370062 | H63: 2.6 | I63: 3.6789298 | J63: 7.1868583 | K63: 4.6632124 | L63: 6.2626263 | M63: 5.2884615 | N63: 3.4358047 | O63: 6.7729084 | P63: 4.8096192 | Q63: 7.6225045 | R63: 5.3380783 | S63: 4.3785311 | T63: 4.0160643 | U63: 5.0458716 | V63: 4.6546547 | W63: 4.0816327 | X63: 8.0188679 | Y63: 7.082153 | Z63: 0 | AA63: 2.5362319 | AB63: 5.5743243 | AC63: 3.4129693 | AD63: 6.1482821 | AE63: 4.7787611 | AF63: 13.932981 | AG63: 6.0344828 | AH63: 4.3936731 | AI63: -11.682119 | AJ63: 1.8867925 | AK63: 0.11185682 | AL63: 1.1597938 | AM63: 9.8901099 | AN63: 8.8505747 | AO63: 9.0497738 | AP63: 8.9463221 | AQ63: 6.7567568 | AR63: 10.882353 | AS63: 5.0505051 | AT63: 4.2836041 | AU63: 7.0981211 | AV63: 3.3391916
A64: 41729 | B64: 6.1403509 | C64: 5.6291391 | D64: 9.3167702 | E64: 4.0856031 | F64: 7.5630252 | G64: 7.2016461 | H64: 4.4088176 | I64: 5.1495017 | J64: 12.761506 | K64: 6.3451777 | L64: 7.1138211 | M64: 5.5690073 | N64: 3.9783002 | O64: 7.1017274 | P64: 6.0665362 | Q64: 5.3097345 | R64: 6.2608696 | S64: 4.6544429 | T64: 4.5454545 | U64: 4.9848943 | V64: 5.2005944 | W64: 4.1907514 | X64: 8.0188679 | Y64: 7.082153 | Z64: 0.25929127 | AA64: 2.7811366 | AB64: 5.6856187 | AC64: 4.109589 | AD64: 6.1482821 | AE64: 4.9469965 | AF64: 9.4370861 | AG64: 4.9319728 | AH64: 6.4798599 | AI64: -10.183684 | AJ64: 0.7253886 | AK64: -0.77777778 | AL64: 1.1597938 | AM64: 11.816193 | AN64: 7.5892857 | AO64: 8.5062241 | AP64: 9.3065693 | AQ64: 7.2657744 | AR64: 10.964912 | AS64: 6.1461794 | AT64: 4.2836041 | AU64: 6.875 | AV64: 3.6906854
